<robot name="onshape">
<link name="link_arm_hinge">
<visual>
<origin xyz="0 0 -3.5236570605778894105e-18" rpy="0 -0 0" />
<geometry>
<mesh filename="package:///link_arm_hinge.stl"/>
</geometry>
<material name="link_arm_hinge_material">
<color rgba="0.61568627450980395466 0.81176470588235294379 0.92941176470588238168 1.0"/>
</material>
</visual>
<collision>
<origin xyz="0 0 -3.5236570605778894105e-18" rpy="0 -0 0" />
<geometry>
<mesh filename="package:///link_arm_hinge.stl"/>
</geometry>
</collision>
<inertial>
<origin xyz="0 0 0" rpy="0 0 0"/>
<mass value="0" />
<inertia ixx="0" ixy="0"  ixz="0" iyy="0" iyz="0" izz="0" />
</inertial>
</link>

<link name="link_arm__list_bssx4km84nfaeg_default">
<visual>
<origin xyz="-1.1664760761878812374e-18 1.1664760761878796966e-18 -0.01905000000000000096" rpy="3.141592653589793116 -1.570796326794896558 0" />
<geometry>
<mesh filename="package:///link_arm__list_bssx4km84nfaeg_default.stl"/>
</geometry>
<material name="link_arm__list_bssx4km84nfaeg_default_material">
<color rgba="0.70196078431372543882 0.70196078431372543882 0.70196078431372543882 1.0"/>
</material>
</visual>
<collision>
<origin xyz="-1.1664760761878812374e-18 1.1664760761878796966e-18 -0.01905000000000000096" rpy="3.141592653589793116 -1.570796326794896558 0" />
<geometry>
<mesh filename="package:///link_arm__list_bssx4km84nfaeg_default.stl"/>
</geometry>
</collision>
<inertial>
<origin xyz="0.31749999999999994893 -2.2990548425592210141e-18 -0.019050000000000021777" rpy="0 0 0"/>
<mass value="0.35393517414960223855" />
<inertia ixx="0.00010882057682981095879" ixy="-4.4091004162436268114e-20"  ixz="7.2490205255864722639e-19" iyy="0.01194736950478768843" iyz="-3.818762239942689053e-35" izz="0.01194736950478768843" />
</inertial>
</link>

<joint name="joint_1" type="revolute">
<origin xyz="-1.9370784210903377092e-16 0 -2.0573867649324785651e-16" rpy="1.570796326794896558 0.77835292663939559255 -3.141592653589793116" />
<parent link="link_arm_hinge" />
<child link="link_arm__list_bssx4km84nfaeg_default" />
<axis xyz="0 0 1"/>
<limit effort="1" velocity="20" />
<joint_properties friction="0.0"/>
</joint>


</robot>
