<?xml version="1.0" encoding="utf-8"?>
<!-- This URDF was automatically created by SolidWorks to URDF Exporter! Originally created by Stephen Brawner (brawner@gmail.com) 
     Commit Version: 1.6.0-4-g7f85cfe  Build Version: 1.6.7995.38578
     For more information, please see http://wiki.ros.org/sw_urdf_exporter -->
<robot
  name="arm_first_try">
  <link
    name="base_link">
    <inertial>
      <origin
        xyz="0.022654 0.039762 0.052593"
        rpy="0 0 0" />
      <mass
        value="4.1507" />
      <inertia
        ixx="0.0060784"
        ixy="3.4186E-36"
        ixz="0"
        iyy="0.0060784"
        iyz="-1.1461E-35"
        izz="0.0087307" />
    </inertial>
    <visual>
      <origin
        xyz="0 0 0"
        rpy="0 0 0" />
      <geometry>
        <mesh
          filename="package://urdf_visualization/urdf/meshes_2/base_link.STL" />
      </geometry>
      <material
        name="">
        <color
          rgba="0.52941 0.54902 0.54902 1" />
      </material>
    </visual>
    <collision>
      <origin
        xyz="0 0 0"
        rpy="0 0 0" />
      <geometry>
        <mesh
          filename="package://urdf_visualization/urdf/meshes_2/base_link.STL" />
      </geometry>
    </collision>
  </link>
  <link
    name="link_1">
    <inertial>
      <origin
        xyz="2.1313E-09 -0.0060695 0.64486"
        rpy="0 0 0" />
      <mass
        value="5.297" />
      <inertia
        ixx="0.018364"
        ixy="5.3984E-09"
        ixz="1.7903E-09"
        iyy="0.02005"
        iyz="9.0873E-18"
        izz="0.0077173" />
    </inertial>
    <visual>
      <origin
        xyz="0 0 0"
        rpy="0 0 0" />
      <geometry>
        <mesh
          filename="package://urdf_visualization/urdf/meshes_2/link_1.STL" />
      </geometry>
      <material
        name="">
        <color
          rgba="0.79608 0.82353 0.93725 1" />
      </material>
    </visual>
    <collision>
      <origin
        xyz="0 0 0"
        rpy="0 0 0" />
      <geometry>
        <mesh
          filename="package://urdf_visualization/urdf/meshes_2/link_1.STL" />
      </geometry>
    </collision>
  </link>
  <joint
    name="joint_1"
    type="revolute">
    <origin
      xyz="0.022654 -0.16716 0.027062"
      rpy="0 0 3.1416" />
    <parent
      link="base_link" />
    <child
      link="link_1" />
    <axis
      xyz="0 1 0" />
    <limit
      lower="-1.5707"
      upper="1.5707"
      effort="63"
      velocity="10" />
  </joint>
  <link
    name="link_2">
    <inertial>
      <origin
        xyz="-1.1102E-16 -0.046379 -0.099157"
        rpy="0 0 0" />
      <mass
        value="0.69319" />
      <inertia
        ixx="0.0097843"
        ixy="7.7351E-19"
        ixz="-1.5777E-18"
        iyy="0.0088081"
        iyz="1.4603E-20"
        izz="0.0013707" />
    </inertial>
    <visual>
      <origin
        xyz="0 0 0"
        rpy="0 0 0" />
      <geometry>
        <mesh
          filename="package://urdf_visualization/urdf/meshes_2/link_2.STL" />
      </geometry>
      <material
        name="">
        <color
          rgba="0.79608 0.82353 0.93725 1" />
      </material>
    </visual>
    <collision>
      <origin
        xyz="0 0 0"
        rpy="0 0 0" />
      <geometry>
        <mesh
          filename="package://urdf_visualization/urdf/meshes_2/link_2.STL" />
      </geometry>
    </collision>
  </link>
  <joint
    name="joint_2"
    type="revolute">
    <origin
      xyz="0.0127 0.11456 0.73061"
      rpy="6.2832 -1.5708 0" />
    <parent
      link="link_1" />
    <child
      link="link_2" />
    <axis
      xyz="0 1 0" />
    <limit
      lower="0"
      upper="3.1416"
      effort="33"
      velocity="10" />
  </joint>
  <link
    name="link_3">
    <inertial>
      <origin
        xyz="0.012383 0.048193 -2.2204E-16"
        rpy="0 0 0" />
      <mass
        value="0.20963" />
      <inertia
        ixx="0.00033433"
        ixy="1.1858E-19"
        ixz="-3.5906E-20"
        iyy="0.00010201"
        iyz="1.139E-20"
        izz="0.00027774" />
    </inertial>
    <visual>
      <origin
        xyz="0 0 0"
        rpy="0 0 0" />
      <geometry>
        <mesh
          filename="package://urdf_visualization/urdf/meshes_2/link_3.STL" />
      </geometry>
      <material
        name="">
        <color
          rgba="0.79608 0.82353 0.93725 1" />
      </material>
    </visual>
    <collision>
      <origin
        xyz="0 0 0"
        rpy="0 0 0" />
      <geometry>
        <mesh
          filename="package://urdf_visualization/urdf/meshes_2/link_3.STL" />
      </geometry>
    </collision>
  </link>
  <joint
    name="joint_3"
    type="revolute">
    <origin
      xyz="0 -0.012382 -0.5969"
      rpy="-1.5708 0 1.5708" />
    <parent
      link="link_2" />
    <child
      link="link_3" />
    <axis
      xyz="0 1 0" />
    <limit
      lower="0"
      upper="3.1416"
      effort="24"
      velocity="3" />
  </joint>
</robot>