<?xml version="1.0" encoding="utf-8"?>
<!-- This URDF was automatically created by SolidWorks to URDF Exporter! Originally created by Stephen Brawner (brawner@gmail.com) 
     Commit Version: 1.6.0-4-g7f85cfe  Build Version: 1.6.7995.38578
     For more information, please see http://wiki.ros.org/sw_urdf_exporter -->
<robot
  name="arm">
  <link
    name="base_link">
    <inertial>
      <origin
        xyz="2.53269627492614E-16 0.0351875 -1.11022302462516E-16"
        rpy="0 0 0" />
      <mass
        value="4.15068574213693" />
      <inertia
        ixx="0.00607844500433802"
        ixy="1.85209295977699E-17"
        ixz="-6.46688986627396E-32"
        iyy="0.00873074753732344"
        iyz="-9.26046479888497E-18"
        izz="0.00607844500433802" />
    </inertial>
    <visual>
      <origin
        xyz="0 0 0"
        rpy="0 0 0" />
      <geometry>
        <mesh
          filename="package://urdf_visualization/urdf/meshes_2/base_link.STL" />
      </geometry>
      <material
        name="">
        <color
          rgba="0.529411764705882 0.549019607843137 0.549019607843137 1" />
      </material>
    </visual>
    <collision>
      <origin
        xyz="0 0 0"
        rpy="0 0 0" />
      <geometry>
        <mesh
          filename="package://urdf_visualization/urdf/meshes_2/base_link.STL" />
      </geometry>
    </collision>
  </link>
  <link
    name="link_1">
    <inertial>
      <origin
        xyz="2.13134236648482E-09 0.143680545586139 0.632164183939745"
        rpy="0 0 0" />
      <mass
        value="5.29698149295367" />
      <inertia
        ixx="0.0183643265008001"
        ixy="5.39843983456981E-09"
        ixz="1.79032050011225E-09"
        iyy="0.0200496748741122"
        iyz="-3.82497627374888E-17"
        izz="0.00771725286735197" />
    </inertial>
    <visual>
      <origin
        xyz="0 0 0"
        rpy="0 0 0" />
      <geometry>
        <mesh
          filename="package://urdf_visualization/urdf/meshes_2/link_1.STL" />
      </geometry>
      <material
        name="">
        <color
          rgba="0.796078431372549 0.823529411764706 0.937254901960784 1" />
      </material>
    </visual>
    <collision>
      <origin
        xyz="0 0 0"
        rpy="0 0 0" />
      <geometry>
        <mesh
          filename="package://urdf_visualization/urdf/meshes_2/link_1.STL" />
      </geometry>
    </collision>
  </link>
  <joint
    name="joint_1"
    type="revolute">
    <origin
      xyz="0 0 0"
      rpy="0 0 0" />
    <parent
      link="base_link" />
    <child
      link="link_1" />
    <axis
      xyz="0 -1 0" />
    <limit
      lower="-1.5707"
      upper="1.5707"
      effort="63"
      velocity="10" />
  </joint>
  <link
    name="link_2">
    <inertial>
      <origin
        xyz="0.111856676864864 0.103370776116097 0.191210999999999"
        rpy="0 0 0" />
      <mass
        value="0.693193740866267" />
      <inertia
        ixx="0.00137070949454265"
        ixy="4.81263882636075E-17"
        ixz="1.54006953767302E-18"
        iyy="0.00880806951345305"
        iyz="4.18461477334338E-18"
        izz="0.00978431925221729" />
    </inertial>
    <visual>
      <origin
        xyz="0 0 0"
        rpy="0 0 0" />
      <geometry>
        <mesh
          filename="package://urdf_visualization/urdf/meshes_2/link_2.STL" />
      </geometry>
      <material
        name="">
        <color
          rgba="0.796078431372549 0.823529411764706 0.937254901960784 1" />
      </material>
    </visual>
    <collision>
      <origin
        xyz="0 0 0"
        rpy="0 0 0" />
      <geometry>
        <mesh
          filename="package://urdf_visualization/urdf/meshes_2/link_2.STL" />
      </geometry>
    </collision>
  </link>
  <joint
    name="joint_2"
    type="revolute">
    <origin
      xyz="0 0.11456 0.52669"
      rpy="0 0 0" />
    <parent
      link="link_1" />
    <child
      link="link_2" />
    <axis
      xyz="0 1 0" />
    <limit
      lower="0"
      upper="3.1416"
      effort="30"
      velocity="10" />
  </joint>
  <link
    name="link_3">
    <inertial>
      <origin
        xyz="0.0354933238733647 2.77555756156289E-16 -1.11022302462516E-16"
        rpy="0 0 0" />
      <mass
        value="0.20963088398212" />
      <inertia
        ixx="0.000102013852414638"
        ixy="1.74762190190723E-18"
        ixz="-1.22356623670395E-20"
        iyy="0.000334330864633171"
        iyz="-1.61734114412616E-19"
        izz="0.000277737972892406" />
    </inertial>
    <visual>
      <origin
        xyz="0 0 0"
        rpy="0 0 0" />
      <geometry>
        <mesh
          filename="package://urdf_visualization/urdf/meshes_2/link_3.STL" />
      </geometry>
      <material
        name="">
        <color
          rgba="0.796078431372549 0.823529411764706 0.937254901960784 1" />
      </material>
    </visual>
    <collision>
      <origin
        xyz="0 0 0"
        rpy="0 0 0" />
      <geometry>
        <mesh
          filename="package://urdf_visualization/urdf/meshes_2/link_3.STL" />
      </geometry>
    </collision>
  </link>
  <joint
    name="joint_3"
    type="revolute">
    <origin
      xyz="0.6223 0.14975 0.19121"
      rpy="0 0 0" />
    <parent
      link="link_2" />
    <child
      link="link_3" />
    <axis
      xyz="-1 0 0" />
    <limit
      lower="0"
      upper="3.1416"
      effort="24"
      velocity="3" />
  </joint>
</robot>