<?xml version="1.0" encoding="utf-8"?>
<!-- This URDF was automatically created by SolidWorks to URDF Exporter! Originally created by Stephen Brawner (brawner@gmail.com) 
     Commit Version: 1.6.0-4-g7f85cfe  Build Version: 1.6.7995.38578
     For more information, please see http://wiki.ros.org/sw_urdf_exporter -->
<robot
  name="arm2_urdf">
  <link
    name="base_link">
    <inertial>
      <origin
        xyz="2.53269627492614E-16 0.0351875 -1.11022302462516E-16"
        rpy="0 0 0" />
      <mass
        value="4.15068574213693" />
      <inertia
        ixx="0.00607844500433802"
        ixy="1.85209295977699E-17"
        ixz="-6.46688986627396E-32"
        iyy="0.00873074753732344"
        iyz="-9.26046479888497E-18"
        izz="0.00607844500433802" />
    </inertial>
    <visual>
      <origin
        xyz="0 0 0"
        rpy="0 0 0" />
      <geometry>
        <mesh
          filename="package://arm_ik/meshes/base_link.STL" />
      </geometry>
      <material
        name="">
        <color
          rgba="0.529411764705882 0.549019607843137 0.549019607843137 1" />
      </material>
    </visual>
    <collision>
      <origin
        xyz="0 0 0"
        rpy="0 0 0" />
      <geometry>
        <mesh
          filename="package://arm_ik/meshes/base_link.STL" />
      </geometry>
    </collision>
  </link>
  <link
    name="link_1">
    <inertial>
      <origin
        xyz="2.16093430649433E-09 0.143596276041462 0.505239789070312"
        rpy="0 0 0" />
      <mass
        value="5.22444424208244" />
      <inertia
        ixx="0.0134223705688452"
        ixy="5.39843983522087E-09"
        ixz="1.79032049981247E-09"
        iyy="0.0151077189421573"
        iyz="-2.76690494655853E-17"
        izz="0.00769097362687298" />
    </inertial>
    <visual>
      <origin
        xyz="0 0 0"
        rpy="0 0 0" />
      <geometry>
        <mesh
          filename="package://arm_ik/meshes/link_1.STL" />
      </geometry>
      <material
        name="">
        <color
          rgba="0.796078431372549 0.823529411764706 0.937254901960784 1" />
      </material>
    </visual>
    <collision>
      <origin
        xyz="0 0 0"
        rpy="0 0 0" />
      <geometry>
        <mesh
          filename="package://arm_ik/meshes/link_1.STL" />
      </geometry>
    </collision>
  </link>
  <joint
    name="joint_1"
    type="revolute">
    <origin
      xyz="0 0 0"
      rpy="0 0 0" />
    <parent
      link="base_link" />
    <child
      link="link_1" />
    <axis
      xyz="0 1 0" />
    <limit
      lower="-1.5707"
      upper="1.5707"
      effort="63"
      velocity="10" />
  </joint>
  <link
    name="link_2">
    <inertial>
      <origin
        xyz="-0.161466721516512 -0.110140432452362 0"
        rpy="0 0 0" />
      <mass
        value="0.811667223175114" />
      <inertia
        ixx="0.00144112638133478"
        ixy="1.22711446997755E-17"
        ixz="3.80344155172408E-19"
        iyy="0.00319599814657966"
        iyz="3.99584744049083E-18"
        izz="0.00411565499360313" />
    </inertial>
    <visual>
      <origin
        xyz="0 0 0"
        rpy="0 0 0" />
      <geometry>
        <mesh
          filename="package://arm_ik/meshes/link_2.STL" />
      </geometry>
      <material
        name="">
        <color
          rgba="0.796078431372549 0.823529411764706 0.937254901960784 1" />
      </material>
    </visual>
    <collision>
      <origin
        xyz="0 0 0"
        rpy="0 0 0" />
      <geometry>
        <mesh
          filename="package://arm_ik/meshes/link_2.STL" />
      </geometry>
    </collision>
  </link>
  <joint
    name="joint_2"
    type="revolute">
    <origin
      xyz="0 0.11456 0.5716"
      rpy="0 0 0" />
    <parent
      link="link_1" />
    <child
      link="link_2" />
    <axis
      xyz="0 1 0" />
    <limit
      lower="-1.5707"
      upper="6.2802"
      effort="30"
      velocity="10" />
  </joint>
  <link
    name="link_3">
    <inertial>
      <origin
        xyz="-1.11022302462516E-16 -0.00935030615849541 4.30211422042248E-16"
        rpy="0 0 0" />
      <mass
        value="0.441934179484334" />
      <inertia
        ixx="0.000580602286707566"
        ixy="8.27474321642412E-20"
        ixz="-3.55034402418239E-20"
        iyy="0.000491950663175556"
        iyz="2.015497179801E-19"
        izz="0.000361938719156181" />
    </inertial>
    <visual>
      <origin
        xyz="0 0 0"
        rpy="0 0 0" />
      <geometry>
        <mesh
          filename="package://arm_ik/meshes/link_3.STL" />
      </geometry>
      <material
        name="">
        <color
          rgba="0.792156862745098 0.819607843137255 0.933333333333333 1" />
      </material>
    </visual>
    <collision>
      <origin
        xyz="0 0 0"
        rpy="0 0 0" />
      <geometry>
        <mesh
          filename="package://arm_ik/meshes/link_3.STL" />
      </geometry>
    </collision>
  </link>
  <joint
    name="joint_3"
    type="revolute">
    <origin
      xyz="-0.50776 -0.14975 0"
      rpy="3.1416 -1.5708 1.5708" />
    <parent
      link="link_2" />
    <child
      link="link_3" />
    <axis
      xyz="0 0 1" />
    <limit
      lower="-1.5707"
      upper="1.5707"
      effort="24"
      velocity="3" />
  </joint>
  <link
    name="link_4">
    <inertial>
      <origin
        xyz="-2.22044604925031E-16 -0.0546473622653039 4.68375338513738E-16"
        rpy="0 0 0" />
      <mass
        value="0.475602149431558" />
      <inertia
        ixx="0.00323678199641303"
        ixy="-2.84626520739531E-18"
        ixz="2.21989723642492E-18"
        iyy="0.00243855886718496"
        iyz="5.8391116076532E-19"
        izz="0.000910817645576703" />
    </inertial>
    <visual>
      <origin
        xyz="0 0 0"
        rpy="0 0 0" />
      <geometry>
        <mesh
          filename="package://arm_ik/meshes/link_4.STL" />
      </geometry>
      <material
        name="">
        <color
          rgba="0.792156862745098 0.819607843137255 0.933333333333333 1" />
      </material>
    </visual>
    <collision>
      <origin
        xyz="0 0 0"
        rpy="0 0 0" />
      <geometry>
        <mesh
          filename="package://arm_ik/meshes/link_4.STL" />
      </geometry>
    </collision>
  </link>
  <joint
    name="joint_4"
    type="revolute">
    <origin
      xyz="0 -0.0381 0"
      rpy="0 0 0" />
    <parent
      link="link_3" />
    <child
      link="link_4" />
    <axis
      xyz="0 -1 0" />
    <limit
      lower="-3.14"
      upper="3.14"
      effort="0"
      velocity="0" />
  </joint>
</robot>