<?xml version="1.0" encoding="utf-8"?>
<!-- This URDF was automatically created by SolidWorks to URDF Exporter! Originally created by Stephen Brawner (brawner@gmail.com) 
     Commit Version: 1.6.0-4-g7f85cfe  Build Version: 1.6.7995.38578
     For more information, please see http://wiki.ros.org/sw_urdf_exporter -->
<robot 
  name="robot_arm_urdf_complete">
  <link
    name="base_link">
    <inertial>
      <origin
        xyz="2.5327E-16 0.035188 -1.1102E-16"
        rpy="0 0 0" />
      <mass
        value="3" />
      <inertia
        ixx="0.0060784"
        ixy="1.8521E-17"
        ixz="-6.4669E-32"
        iyy="0.0087307"
        iyz="-9.2605E-18"
        izz="0.0060784" />
    </inertial>
    <visual>
      <origin
        xyz="0 0 0"
        rpy="0 0 0" />
      <geometry>
        <mesh
          filename="package://arm_ik/meshes/base_link.STL" />
      </geometry>
      <material
        name="">
        <color
          rgba="0.52941 0.54902 0.54902 1" />
      </material>
    </visual>
    <collision>
      <origin
        xyz="0 0 0"
        rpy="0 0 0" />
      <geometry>
        <mesh
          filename="package://arm_ik/meshes/base_link.STL" />
      </geometry>
    </collision>
  </link>
  <link
    name="link_1">
    <inertial>
      <origin
        xyz="2.142E-09 0.14365 0.6139"
        rpy="0 0 0" />
      <mass
        value="5.2706" />
      <inertia
        ixx="0.016945"
        ixy="5.3984E-09"
        ixz="1.7903E-09"
        iyy="0.01863"
        iyz="-4.1483E-17"
        izz="0.0077042" />
    </inertial>
    <visual>
      <origin
        xyz="0 0 0"
        rpy="0 0 0" />
      <geometry>
        <mesh
          filename="package://arm_ik/meshes/link_1.STL" />
      </geometry>
      <material
        name="">
        <color
          rgba="0.79608 0.82353 0.93725 1" />
      </material>
    </visual>
    <collision>
      <origin
        xyz="0 0 0"
        rpy="0 0 0" />
      <geometry>
        <mesh
          filename="package://arm_ik/meshes/link_1.STL" />
      </geometry>
    </collision>
  </link>
  <joint
    name="joint_1"
    type="revolute">
    <origin
      xyz="0 0 0"
      rpy="0 0 0" />
    <parent
      link="base_link" />
    <child
      link="link_1" />
    <axis
      xyz="0 -1 0" />
    <limit
      lower="-1.5707"
      upper="1.5707"
      effort="63"
      velocity="10" />
  </joint>
  <link
    name="link_2">
    <inertial>
      <origin
        xyz="-0.22922 -0.11307 3.3307E-16"
        rpy="0 0 0" />
      <mass
        value="4" />
      <inertia
        ixx="0.0014596"
        ixy="4.4067E-17"
        ixz="1.0177E-18"
        iyy="0.0077228"
        iyz="4.005E-18"
        izz="0.0086424" />
    </inertial>
    <visual>
      <origin
        xyz="0 0 0"
        rpy="0 0 0" />
      <geometry>
        <mesh
          filename="package://arm_ik/meshes/link_2.STL" />
      </geometry>
      <material
        name="">
        <color
          rgba="0.79608 0.82353 0.93725 1" />
      </material>
    </visual>
    <collision>
      <origin
        xyz="0 0 0"
        rpy="0 0 0" />
      <geometry>
        <mesh
          filename="package://arm_ik/meshes/link_2.STL" />
      </geometry>
    </collision>
  </link>
  <joint
    name="joint_2"
    type="revolute">
    <origin
      xyz="0 0.11456 0.69567"
      rpy="0 0 0" />
    <parent
      link="link_1" />
    <child
      link="link_2" />
    <axis
      xyz="0 1 0" />
    <limit
      lower="-1.60"
      upper="3.1416"
      effort="30"
      velocity="10" />
  </joint>
  <link
    name="link_3">
    <inertial>
      <origin
        xyz="-3.3307E-16 -0.0093503 5.5511E-16"
        rpy="0 0 0" />
      <mass
        value="0.44193" />
      <inertia
        ixx="0.0005806"
        ixy="6.0881E-20"
        ixz="1.552E-20"
        iyy="0.00049195"
        iyz="1.0972E-19"
        izz="0.00036194" />
    </inertial>
    <visual>
      <origin
        xyz="0 0 0"
        rpy="0 0 0" />
      <geometry>
        <mesh
          filename="package://arm_ik/meshes/link_3.STL" />
      </geometry>
      <material
        name="">
        <color
          rgba="0.79216 0.81961 0.93333 1" />
      </material>
    </visual>
    <collision>
      <origin
        xyz="0 0 0"
        rpy="0 0 0" />
      <geometry>
        <mesh
          filename="package://arm_ik/meshes/link_3.STL" />
      </geometry>
    </collision>
  </link>
  <joint
    name="joint_3"
    type="revolute">
    <origin
      xyz="-0.68187 -0.14975 0"
      rpy="3.1416 -1.5708 1.5708" />
    <parent
      link="link_2" />
    <child
      link="link_3" />
    <axis
      xyz="0 0 1" />
    <limit
      lower="-1.6"
      upper="1.6"
      effort="24"
      velocity="3" />
  </joint>
  <link
    name="link_4">
    <inertial>
      <origin
        xyz="-3.3307E-16 -0.054647 6.1409E-16"
        rpy="0 0 0" />
      <mass
        value="0.4756" />
      <inertia
        ixx="0.0032368"
        ixy="-2.7595E-18"
        ixz="2.3927E-18"
        iyy="0.0024386"
        iyz="3.9635E-20"
        izz="0.00091082" />
    </inertial>
    <visual>
      <origin
        xyz="0 0 0"
        rpy="0 0 0" />
      <geometry>
        <mesh
          filename="package://arm_ik/meshes/link_4.STL" />
      </geometry>
      <material
        name="">
        <color
          rgba="0.79216 0.81961 0.93333 1" />
      </material>
    </visual>
    <collision>
      <origin
        xyz="0 0 0"
        rpy="0 0 0" />
      <geometry>
        <mesh
          filename="package://arm_ik/meshes/link_4.STL" />
      </geometry>
    </collision>
  </link>
  <joint
    name="joint_4"
    type="revolute">
    <origin
      xyz="0 -0.0381 0"
      rpy="0 0 0" />
    <parent
      link="link_3" />
    <child
      link="link_4" />
    <axis
      xyz="0 -1 0" />
    <limit
      lower="-3.14"
      upper="3.14"
      effort="0"
      velocity="0" />
  </joint>

</robot>